{"trial_id": "1", "hyperparameters": {"space": [{"class_name": "Int", "config": {"name": "rnn_units", "default": null, "conditions": [], "min_value": 16, "max_value": 128, "step": 16, "sampling": "linear"}}, {"class_name": "Choice", "config": {"name": "optimizer", "default": "adam", "conditions": [], "values": ["adam", "sgd"], "ordered": false}}, {"class_name": "Float", "config": {"name": "learning_rate", "default": 0.001, "conditions": [], "min_value": 0.0001, "max_value": 0.01, "step": null, "sampling": "log"}}], "values": {"rnn_units": 48, "optimizer": "sgd", "learning_rate": 0.00022962329968295313}}, "metrics": {"metrics": {}}, "score": null, "best_step": 0, "status": "FAILED", "message": "Traceback (most recent call last):\n  File \"c:\\Python310\\lib\\site-packages\\keras_tuner\\engine\\base_tuner.py\", line 270, in _try_run_and_update_trial\n    self._run_and_update_trial(trial, *fit_args, **fit_kwargs)\n  File \"c:\\Python310\\lib\\site-packages\\keras_tuner\\engine\\base_tuner.py\", line 235, in _run_and_update_trial\n    results = self.run_trial(trial, *fit_args, **fit_kwargs)\n  File \"c:\\Python310\\lib\\site-packages\\keras_tuner\\engine\\tuner.py\", line 287, in run_trial\n    obj_value = self._build_and_fit_model(trial, *args, **copied_kwargs)\n  File \"c:\\Python310\\lib\\site-packages\\keras_tuner\\engine\\tuner.py\", line 214, in _build_and_fit_model\n    results = self.hypermodel.fit(hp, model, *args, **kwargs)\n  File \"c:\\Python310\\lib\\site-packages\\keras_tuner\\engine\\hypermodel.py\", line 144, in fit\n    return model.fit(*args, **kwargs)\n  File \"c:\\Python310\\lib\\site-packages\\keras\\src\\utils\\traceback_utils.py\", line 70, in error_handler\n    raise e.with_traceback(filtered_tb) from None\n  File \"C:\\Users\\Yeojung\\AppData\\Local\\Temp\\__autograph_generated_filek6jy5btg.py\", line 15, in tf__train_function\n    retval_ = ag__.converted_call(ag__.ld(step_function), (ag__.ld(self), ag__.ld(iterator)), None, fscope)\nValueError: in user code:\n\n    File \"c:\\Python310\\lib\\site-packages\\keras\\src\\engine\\training.py\", line 1338, in train_function  *\n        return step_function(self, iterator)\n    File \"c:\\Python310\\lib\\site-packages\\keras\\src\\engine\\training.py\", line 1322, in step_function  **\n        outputs = model.distribute_strategy.run(run_step, args=(data,))\n    File \"c:\\Python310\\lib\\site-packages\\keras\\src\\engine\\training.py\", line 1303, in run_step  **\n        outputs = model.train_step(data)\n    File \"c:\\Python310\\lib\\site-packages\\keras\\src\\engine\\training.py\", line 1081, in train_step\n        loss = self.compute_loss(x, y, y_pred, sample_weight)\n    File \"c:\\Python310\\lib\\site-packages\\keras\\src\\engine\\training.py\", line 1139, in compute_loss\n        return self.compiled_loss(\n    File \"c:\\Python310\\lib\\site-packages\\keras\\src\\engine\\compile_utils.py\", line 265, in __call__\n        loss_value = loss_obj(y_t, y_p, sample_weight=sw)\n    File \"c:\\Python310\\lib\\site-packages\\keras\\src\\losses.py\", line 142, in __call__\n        losses = call_fn(y_true, y_pred)\n    File \"c:\\Python310\\lib\\site-packages\\keras\\src\\losses.py\", line 268, in call  **\n        return ag_fn(y_true, y_pred, **self._fn_kwargs)\n    File \"c:\\Python310\\lib\\site-packages\\keras\\src\\losses.py\", line 2122, in categorical_crossentropy\n        return backend.categorical_crossentropy(\n    File \"c:\\Python310\\lib\\site-packages\\keras\\src\\backend.py\", line 5560, in categorical_crossentropy\n        target.shape.assert_is_compatible_with(output.shape)\n\n    ValueError: Shapes (32, 35) and (32, 35, 35) are incompatible\n\n"}